Workbook
Name Task_Table: Task_Table!$B$2:$D$2
Name Task_Table: 'Copy of Task_Table'!$B$2:$D$2

Sheet Task_Table
B1: PLANNING
B2: Name | C2: Days | D2: Weight | AJ2: April | BN2: Mei | CS2: JUN
E3: 1 | F3: 2 | G3: 3 | H3: 4 | I3: 5 | J3: 6 | K3: 7 | L3: 8 | M3: 9 | N3: 10 | O3: 11 | P3: 12 | Q3: 13 | R3: 14 | S3: 15 | T3: 16 | U3: 17 | V3: 18 | W3: 19 | X3: 20 | Y3: 21 | Z3: 22 | AA3: 23 | AB3: 24 | AC3: 25 | AD3: 26 | AE3: 27 | AF3: 28 | AG3: 29 | AH3: 30 | AI3: 31 | AJ3: 1 | AK3: 2 | AL3: 3 | AM3: 4 | AN3: 5 | AO3: 6 | AP3: 7 | AQ3: 8 | AR3: 9 | AS3: 10 | AT3: 11 | AU3: 12 | AV3: 13 | AW3: 14 | AX3: 15 | AY3: 16 | AZ3: 17 | BA3: 18 | BB3: 19 | BC3: 20 | BD3: 21 | BE3: 22 | BF3: 23 | BG3: 24 | BH3: 25 | BI3: 26 | BJ3: 27 | BK3: 28 | BL3: 29 | BM3: 30 | BN3: 1 | BO3: 2 | BP3: 3 | BQ3: 4 | BR3: 5 | BS3: 6 | BT3: 7 | BU3: 8 | BV3: 9 | BW3: 10 | BX3: 11 | BY3: 12 | BZ3: 13 | CA3: 14 | CB3: 15 | CC3: 16 | CD3: 17 | CE3: 18 | CF3: 19 | CG3: 20 | CH3: 21 | CI3: 22 | CJ3: 23 | CK3: 24 | CL3: 25 | CM3: 26 | CN3: 27 | CO3: 28 | CP3: 29 | CQ3: 30 | CR3: 31 | CS3: 1 | CT3: 2 | CU3: 3 | CV3: 4 | CW3: 5 | CX3: 6 | CY3: 7 | CZ3: 8 | DA3: 9 | DB3: 10 | DC3: 11 | DD3: 12 | DE3: 13 | DF3: 14 | DG3: 15 | DH3: 16 | DI3: 17 | DJ3: 18 | DK3: 19 | DL3: 20 | DM3: 21 | DN3: 22 | DO3: 23 | DP3: 24 | DQ3: 25 | DR3: 26 | DS3: 27 | DT3: 28 | DU3: 29 | DV3: 30
A4: Termin 1 30 % | B4: SIGMA Implementation Task | C4: 115 | D4: 100
B5: Fase 1 | D5: =D6+D8 -> 30
B6: Project Preparation | C6: =SUM(C7) -> 2 | D6: =SUM(D7) -> 1
B7: Kick Off | C7: 2 | D7: =SUM(E7:DV7) -> 1 | G7: 1
B8: Requirement Preparation | C8: =SUM(C9:C10) -> 14 | D8: =SUM(D9:D11) -> 29
B9: Gap Analysis | C9: 5 | D9: =SUM(E9:DV9) -> 6 | I9: 1 | J9: 1 | K9: 1 | P9: 1 | Q9: 1 | R9: 1
B10: Blue Print | C10: 9 | D10: =SUM(E10:DV10) -> 6 | U10: 1 | V10: 1 | W10: 1 | AB10: 1 | AC10: 1 | AD10: 1
B11: Mockup | C11: 9 | D11: =SUM(E11:DV11) -> 17 | H11: 1 | I11: 1 | J11: 1 | K11: 1 | N11: 1 | O11: 1 | P11: 1 | Q11: 1 | R11: 1 | U11: 1 | V11: 1 | W11: 1 | X11: 1 | Y11: 1 | AB11: 1 | AC11: 1 | AD11: 1
A12: Termin 2 65 % | B12: Fase 2 | D12: =D13+D17 -> 65
B13: Enhanchement | C13: =SUM(C14:C15:C16) -> 22 | D13: =SUM(D14:D16) -> 49
B14: Environment Preparation | C14: 2 | D14: 1 | K14: 1
B15: Development | C15: 15 | D15: =SUM(E15:DV15) -> 45 | AE15: 1 | AF15: 1 | AQ15: 1 | AR15: 1 | AS15: 1 | AT15: 1 | AW15: 1 | AX15: 1 | AY15: 1 | AZ15: 1 | BA15: 1 | BD15: 1 | BE15: 1 | BF15: 1 | BG15: 1 | BH15: 1 | BK15: 1 | BL15: 1 | BM15: 1 | BN15: 1 | BO15: 1 | BR15: 1 | BS15: 1 | BT15: 1 | BU15: 1 | BV15: 1 | BY15: 1 | BZ15: 1 | CA15: 1 | CB15: 1 | CC15: 1 | CF15: 1 | CG15: 1 | CH15: 1 | CI15: 1 | CJ15: 1 | CM15: 1 | CN15: 1 | CO15: 1 | CP15: 1 | CQ15: 1 | CT15: 1 | CU15: 1 | CV15: 1 | CW15: 0.5 | CX15: 0.5
B16: Unit Testing | C16: 5 | D16: =SUM(E16:DV16) -> 3 | DA16: 1 | DB16: 1 | DC16: 1
B17: Acceptance | C17: =SUM(C18:C19:C20) -> 10 | D17: =SUM(D18:D20) -> 16
B18: SIT | C18: 3 | D18: =SUM(E18:DV18) -> 3 | DC18: 1 | DD18: 1 | DE18: 1
B19: UAT | C19: 4 | D19: =SUM(E19:DV19) -> 10 | DH19: 2 | DI19: 2 | DJ19: 2 | DK19: 2 | DL19: 2
B20: EUT | C20: 3 | D20: =SUM(E20:DV20) -> 3 | DO20: 2 | DP20: 1
A21: Termin 3 5 % | B21: Fase 3 | D21: =D22 -> 5
B22: Support | C22: =SUM(C23) -> 60 | D22: =D23 -> 5
B23: Support | C23: 60 | D23: =SUM(E23:DV23) -> 5 | DQ23: 1 | DR23: 1 | DS23: 1 | DV23: 2
B24: Total | C24: =sum(C22+C17+C13+C8+C6) -> 108 | D24: =D6+D8+D13+D17+D21 -> 100 | E24: =SUM(E4:E23) -> 0 | F24: =SUM(F4:F23) -> 0 | G24: =SUM(G4:G23) -> 1 | H24: =SUM(H4:H23) -> 1 | I24: =SUM(I4:I23) -> 2 | J24: =SUM(J4:J23) -> 2 | K24: =SUM(K4:K23) -> 3 | L24: =SUM(L4:L23) -> 0 | ... AH24: =SUM(AH4:AH23) -> 0 | AJ24: =SUM(AJ4:AJ23) -> 0 | AK24: =SUM(AK4:AK23) -> 0 | AL24: =SUM(AL4:AL23) -> 0 | AM24: =SUM(AM4:AM23) -> 0 | AN24: =SUM(AN4:AN23) -> 0 | AO24: =SUM(AO4:AO23) -> 0 | AP24: =SUM(AP4:AP23) -> 0 | AQ24: =SUM(AQ4:AQ23) -> 1 | ... DV24: =SUM(DV4:DV23) -> 2
B25: Accumulated | E25: =E24 -> 0 | F25: =F24+E25 -> 0 | G25: =G24+F25 -> 1 | H25: =H24+G25 -> 2 | I25: =I24+H25 -> 4 | J25: =J24+I25 -> 6 | K25: =K24+J25 -> 9 | L25: =L24+K25 -> 9 | M25: =M24+L25 -> 9 | ... AH25: =AH24+AG25 -> 33 | AJ25: =AJ24+AH25 -> 33 | AK25: =AK24+AJ25 -> 33 | AL25: =AL24+AK25 -> 33 | AM25: =AM24+AL25 -> 33 | AN25: =AN24+AM25 -> 33 | AO25: =AO24+AN25 -> 33 | AP25: =AP24+AO25 -> 33 | AQ25: =AQ24+AP25 -> 34 | AR25: =AR24+AQ25 -> 35 | ... DV25: =DV24+DU25 -> 100
B28: REAL
B29: Name | C29: Planning | D29: Real | AJ29: April | BN29: Mei | CS29: JUN
E30: 1 | F30: 2 | G30: 3 | H30: 4 | I30: 5 | J30: 6 | K30: 7 | L30: 8 | M30: 9 | N30: 10 | O30: 11 | P30: 12 | Q30: 13 | R30: 14 | S30: 15 | T30: 16 | U30: 17 | V30: 18 | W30: 19 | X30: 20 | Y30: 21 | Z30: 22 | AA30: 23 | AB30: 24 | AC30: 25 | AD30: 26 | AE30: 27 | AF30: 28 | AG30: 29 | AH30: 30 | AI30: 31 | AJ30: 1 | AK30: 2 | AL30: 3 | AM30: 4 | AN30: 5 | AO30: 6 | AP30: 7 | AQ30: 8 | AR30: 9 | AS30: 10 | AT30: 11 | AU30: 12 | AV30: 13 | AW30: 14 | AX30: 15 | AY30: 16 | AZ30: 17 | BA30: 18 | BB30: 19 | BC30: 20 | BD30: 21 | BE30: 22 | BF30: 23 | BG30: 24 | BH30: 25 | BI30: 26 | BJ30: 27 | BK30: 28 | BL30: 29 | BM30: 30 | BN30: 1 | BO30: 2 | BP30: 3 | BQ30: 4 | BR30: 5 | BS30: 6 | BT30: 7 | BU30: 8 | BV30: 9 | BW30: 10 | BX30: 11 | BY30: 12 | BZ30: 13 | CA30: 14 | CB30: 15 | CC30: 16 | CD30: 17 | CE30: 18 | CF30: 19 | CG30: 20 | CH30: 21 | CI30: 22 | CJ30: 23 | CK30: 24 | CL30: 25 | CM30: 26 | CN30: 27 | CO30: 28 | CP30: 29 | CQ30: 30 | CR30: 31 | CS30: 1 | CT30: 2 | CU30: 3 | CV30: 4 | CW30: 5 | CX30: 6 | CY30: 7 | CZ30: 8 | DA30: 9 | DB30: 10 | DC30: 11 | DD30: 12 | DE30: 13 | DF30: 14 | DG30: 15 | DH30: 16 | DI30: 17 | DJ30: 18 | DK30: 19 | DL30: 20 | DM30: 21 | DN30: 22 | DO30: 23 | DP30: 24 | DQ30: 25 | DR30: 26 | DS30: 27 | DT30: 28 | DU30: 29 | DV30: 30
A31: Termin 1 30 % | B31: SIGMA Implementation Task | C31: 100 | D31: 100
B32: Fase 1 | C32: 30 | D32: =D33+D35 -> 8.3
B33: Project Preparation | C33: 1 | D33: =SUM(D34) -> 1
B34: Kick Off | C34: 1 | D34: =SUM(E34:DV34) -> 1 | G34: 1
B35: Requirement Preparation | C35: 29 | D35: =SUM(D36:D38) -> 7.3
B36: Gap Analysis | C36: 6 | D36: =SUM(E36:DV36) -> 3.5 | G36: 1 | H36: 1 | I36: 0.5 | J36: 0.5 | K36: 0.5
B37: Blue Print | C37: 6 | D37: =SUM(E37:DV37) -> 1.9 | G37: 0.2 | H37: 0.2 | I37: 0.5 | J37: 0.5 | K37: 0.5
B38: Mockup | C38: 17 | D38: =SUM(E38:DV38) -> 1.9 | G38: 0.2 | H38: 0.2 | I38: 0.5 | J38: 0.5 | K38: 0.5
A39: Termin 2 65 % | B39: Fase 2 | C39: 65 | D39: =D40+D44 -> 0
B40: Enhanchement | C40: 49 | D40: =SUM(D41:D43) -> 0
B41: Environment Preparation | C41: 1 | D41: =SUM(E41:DV41) -> 0
B42: Development | C42: 45 | D42: =SUM(E42:DV42) -> 0
...

Sheet Copy of Task_Table
B1: PLANNING
B2: Name | C2: Days | D2: Weight | E2: Maret | AJ2: April | BN2: Mei | CS2: JUN | DW2: JUL | FB2: AGUSTUS | GG2: SEPTEMBER
E3: 1 | F3: 2 | G3: 3 | H3: 4 | I3: 5 | J3: 6 | K3: 7 | L3: 8 | M3: 9 | N3: 10 | O3: 11 | P3: 12 | Q3: 13 | R3: 14 | S3: 15 | T3: 16 | U3: 17 | V3: 18 | W3: 19 | X3: 20 | Y3: 21 | Z3: 22 | AA3: 23 | AB3: 24 | AC3: 25 | AD3: 26 | AE3: 27 | AF3: 28 | AG3: 29 | AH3: 30 | AI3: 31 | AJ3: 1 | AK3: 2 | AL3: 3 | AM3: 4 | AN3: 5 | AO3: 6 | AP3: 7 | AQ3: 8 | AR3: 9 | AS3: 10 | AT3: 11 | AU3: 12 | AV3: 13 | AW3: 14 | AX3: 15 | AY3: 16 | AZ3: 17 | BA3: 18 | BB3: 19 | BC3: 20 | BD3: 21 | BE3: 22 | BF3: 23 | BG3: 24 | BH3: 25 | BI3: 26 | BJ3: 27 | BK3: 28 | BL3: 29 | BM3: 30 | BN3: 1 | BO3: 2 | BP3: 3 | BQ3: 4 | BR3: 5 | BS3: 6 | BT3: 7 | BU3: 8 | BV3: 9 | BW3: 10 | BX3: 11 | BY3: 12 | BZ3: 13 | CA3: 14 | CB3: 15 | CC3: 16 | CD3: 17 | CE3: 18 | CF3: 19 | CG3: 20 | CH3: 21 | CI3: 22 | CJ3: 23 | CK3: 24 | CL3: 25 | CM3: 26 | CN3: 27 | CO3: 28 | CP3: 29 | CQ3: 30 | CR3: 31 | CS3: 1 | CT3: 2 | CU3: 3 | CV3: 4 | CW3: 5 | CX3: 6 | CY3: 7 | CZ3: 8 | DA3: 9 | DB3: 10 | DC3: 11 | DD3: 12 | DE3: 13 | DF3: 14 | DG3: 15 | DH3: 16 | DI3: 17 | DJ3: 18 | DK3: 19 | DL3: 20 | DM3: 21 | DN3: 22 | DO3: 23 | DP3: 24 | DQ3: 25 | DR3: 26 | DS3: 27 | DT3: 28 | DU3: 29 | DV3: 30 | DW3: 1 | DX3: 2 | DY3: 3 | DZ3: 4 | EA3: 5 | EB3: 6 | EC3: 7 | ED3: 8 | EE3: 9 | EF3: 10 | EG3: 11 | EH3: 12 | EI3: 13 | EJ3: 14 | EK3: 15 | EL3: 16 | EM3: 17 | EN3: 18 | EO3: 19 | EP3: 20 | EQ3: 21 | ER3: 22 | ES3: 23 | ET3: 24 | EU3: 25 | EV3: 26 | EW3: 27 | EX3: 28 | EY3: 29 | EZ3: 30 | FA3: 31 | FB3: 1 | FC3: 2 | FD3: 3 | FE3: 4 | FF3: 5 | FG3: 6 | FH3: 7 | FI3: 8 | FJ3: 9 | FK3: 10 | FL3: 11 | FM3: 12 | FN3: 13 | FO3: 14 | FP3: 15 | FQ3: 16 | FR3: 17 | FS3: 18 | FT3: 19 | FU3: 20 | FV3: 21 | FW3: 22 | FX3: 23 | FY3: 24 | FZ3: 25 | GA3: 26 | GB3: 27 | GC3: 28 | GD3: 29 | GE3: 30 | GF3: 31 | GG3: 1 | GH3: 2 | GI3: 3 | GJ3: 4 | GK3: 5 | GL3: 6 | GM3: 7 | GN3: 8 | GO3: 9 | GP3: 10 | GQ3: 11 | GR3: 12 | GS3: 13 | GT3: 14 | GU3: 15 | GV3: 16 | GW3: 17 | GX3: 18 | GY3: 19 | GZ3: 20 | HA3: 21 | HB3: 22 | HC3: 23 | HD3: 24 | HE3: 25 | HF3: 26 | HG3: 27 | HH3: 28 | HI3: 29 | HJ3: 30
A4: Termin 1 30 % | B4: MD ROYALTY Implementation Task | C4: 115 | D4: 100
B5: TERMIN 1 | D5: =D6+D9 -> 30
B6: Project Preparation | C6: =SUM(C7:C8) -> 4 | D6: =SUM(D7:D8) -> 5
B7: Kick Off | C7: 2 | D7: =SUM(E7:EZ7) -> 2 | E7: 1 | J7: 1
B8: Project Charter | C8: 2 | D8: =SUM(E8:EZ8) -> 3 | J8: 1 | L8: 1 | S8: 1
B9: Requirement Preparation | C9: =SUM(C10:C11) -> 14 | D9: =SUM(D10:D11) -> 25
B10: Gap Analysis | C10: 5 | D10: =SUM(E10:EZ10) -> 10 | K10: 1 | L10: 1 | Q10: 1 | R10: 1 | S10: 1 | V10: 1 | W10: 1 | X10: 1 | Y10: 1 | Z10: 1
B11: Blue Print | C11: 9 | D11: =SUM(E11:EZ11) -> 15 | V11: 1 | W11: 1 | X11: 1 | Y11: 1 | Z11: 1 | AC11: 2 | AD11: 2 | AE11: 2 | AF11: 2 | AG11: 2
A12: Termin 2 65 % | B12: Termin 2 | D12: =D13+D17+D21+D24+D25 -> 69
B13: Enhanchement | C13: =SUM(C14:C15:C16) -> 22 | D13: =SUM(D14:D16) -> 33
B14: Environment Preparation | C14: 2 | D14: =SUM(E14:EZ14) -> 2 | L14: 1 | S14: 1
B15: Development | C15: 15 | D15: =SUM(E15:EZ15) -> 26 | V15: 1 | W15: 1 | X15: 1 | Y15: 1 | Z15: 1 | AC15: 1 | AD15: 1 | AE15: 1 | AF15: 1 | AG15: 1 | AJ15: 1 | AK15: 1 | AL15: 1 | AM15: 1 | AN15: 1 | AX15: 1 | AY15: 1 | AZ15: 1 | BA15: 1 | BB15: 1 | BE15: 1 | BF15: 1 | BG15: 1 | BH15: 1 | BI15: 1 | BL15: 1
B16: Unit Testing | C16: 5 | D16: =SUM(E16:EZ16) -> 5 | BL16: 1 | BM16: 1 | BN16: 1 | CN16: 1 | CO16: 1
B17: Acceptance | C17: =SUM(C18:C19:C20) -> 10 | D17: =SUM(D18:D20) -> 20
B18: SIT | C18: 3 | D18: =SUM(E18:HJ18) -> 5 | BS18: 1 | BT18: 1 | BU18: 1 | CY18: 2
B19: UAT | C19: 4 | D19: =SUM(E19:HJ19) -> 10 | BZ19: 2 | CA19: 2 | CB19: 1 | CC19: 1 | CD19: 1 | CG19: 1 | DP19: 1 | DQ19: 1
B20: EUT | C20: 3 | D20: =SUM(E20:HJ20) -> 5 | CY20: 3 | EG20: 1 | EK20: 1
B21: Live Preparation | C21: =SUM(C22:C25) -> 7 | D21: =SUM(D22:D23) -> 13
B22: Migration Data Preparation | C22: 3 | D22: =SUM(E22:HJ22) -> 8 | DI22: 1 | DJ22: 1 | DK22: 1 | DL22: 1 | DM22: 1 | DP22: 1 | DQ22: 1 | ED22: 1
B23: Upload Migration to Production | C23: 2 | D23: =SUM(E23:HJ23) -> 5 | DR23: 1 | DX23: 1 | FA23: 1 | FH23: 1 | FO23: 1
B24: Transport Production | D24: =SUM(E24:HJ24) -> 2 | ET24: 1 | FT24: 1
B25: Golive | C25: 2 | D25: =SUM(E25:HJ25) -> 1 | GG25: 1
A26: Termin 3 5 % | B26: Termin 3 | D26: =D27 -> 1
B27: Support | C27: =SUM(C28) -> 60 | D27: =D28 -> 1
B28: Support | C28: 60 | D28: =SUM(E28:HJ28) -> 1 | GH28: 1
B29: Total | C29: =sum(C27+C21+C17+C13+C9+C6) -> 117 | D29: =D5+D12+D26 -> 100 | E29: =SUM(E4:E28) -> 1 | F29: =SUM(F4:F28) -> 0 | G29: =SUM(G4:G28) -> 0 | H29: =SUM(H4:H28) -> 0 | I29: =SUM(I4:I28) -> 0 | J29: =SUM(J4:J28) -> 2 | K29: =SUM(K4:K28) -> 1 | L29: =SUM(L4:L28) -> 3 | ... HJ29: =SUM(HJ4:HJ28) -> 0
B30: Accumulated | E30: =E29+D30 -> 1 | F30: =F29+E30 -> 1 | G30: =G29+F30 -> 1 | H30: =H29+G30 -> 1 | I30: =I29+H30 -> 1 | J30: =J29+I30 -> 3 | K30: =K29+J30 -> 4 | L30: =L29+K30 -> 7 | ... HJ30: =HJ29+HI30 -> 100
B33: ACTUAL
B34: Name | C34: Planning | D34: Actual | E34: Maret | AJ34: April | BN34: Mei | CS34: JUN | DW34: JUL | FB34: AGUSTUS | GG34: SEPTEMBER
E35: 1 | F35: 2 | G35: 3 | H35: 4 | I35: 5 | J35: 6 | K35: 7 | L35: 8 | M35: 9 | N35: 10 | O35: 11 | P35: 12 | Q35: 13 | R35: 14 | S35: 15 | T35: 16 | U35: 17 | V35: 18 | W35: 19 | X35: 20 | Y35: 21 | Z35: 22 | AA35: 23 | AB35: 24 | AC35: 25 | AD35: 26 | AE35: 27 | AF35: 28 | AG35: 29 | AH35: 30 | AI35: 31 | AJ35: 1 | AK35: 2 | AL35: 3 | AM35: 4 | AN35: 5 | AO35: 6 | AP35: 7 | AQ35: 8 | AR35: 9 | AS35: 10 | AT35: 11 | AU35: 12 | AV35: 13 | AW35: 14 | AX35: 15 | AY35: 16 | AZ35: 17 | BA35: 18 | BB35: 19 | BC35: 20 | BD35: 21 | BE35: 22 | BF35: 23 | BG35: 24 | BH35: 25 | BI35: 26 | BJ35: 27 | BK35: 28 | BL35: 29 | BM35: 30 | BN35: 1 | BO35: 2 | BP35: 3 | BQ35: 4 | BR35: 5 | BS35: 6 | BT35: 7 | BU35: 8 | BV35: 9 | BW35: 10 | BX35: 11 | BY35: 12 | BZ35: 13 | CA35: 14 | CB35: 15 | CC35: 16 | CD35: 17 | CE35: 18 | CF35: 19 | CG35: 20 | CH35: 21 | CI35: 22 | CJ35: 23 | CK35: 24 | CL35: 25 | CM35: 26 | CN35: 27 | CO35: 28 | CP35: 29 | CQ35: 30 | CR35: 31 | CS35: 1 | CT35: 2 | CU35: 3 | CV35: 4 | CW35: 5 | CX35: 6 | CY35: 7 | CZ35: 8 | DA35: 9 | DB35: 10 | DC35: 11 | DD35: 12 | DE35: 13 | DF35: 14 | DG35: 15 | DH35: 16 | DI35: 17 | DJ35: 18 | DK35: 19 | DL35: 20 | DM35: 21 | DN35: 22 | DO35: 23 | DP35: 24 | DQ35: 25 | DR35: 26 | DS35: 27 | DT35: 28 | DU35: 29 | DV35: 30 | DW35: 1 | DX35: 2 | DY35: 3 | DZ35: 4 | EA35: 5 | EB35: 6 | EC35: 7 | ED35: 8 | EE35: 9 | EF35: 10 | EG35: 11 | EH35: 12 | EI35: 13 | EJ35: 14 | EK35: 15 | EL35: 16 | EM35: 17 | EN35: 18 | EO35: 19 | EP35: 20 | EQ35: 21 | ER35: 22 | ES35: 23 | ET35: 24 | EU35: 25 | EV35: 26 | EW35: 27 | EX35: 28 | EY35: 29 | EZ35: 30 | FA35: 31 | FB35: 1 | FC35: 2 | FD35: 27 | FE35: 28 | FF35: 5 | FG35: 6 | FH35: 7 | FI35: 8 | FJ35: 9 | FK35: 27 | FL35: 28 | FM35: 12 | FN35: 13 | FO35: 14 | FP35: 15 | FQ35: 16 | FR35: 27 | FS35: 28 | FT35: 19 | FU35: 20 | FV35: 21 | FW35: 22 | FX35: 23 | FY35: 27 | FZ35: 28 | GA35: 26 | GB35: 27 | GC35: 28 | GD35: 29 | GE35: 30 | GF35: 27 | GG35: 28 | GH35: 2 | GI35: 3 | GJ35: 4 | GK35: 5 | GL35: 6 | GM35: 27 | GN35: 28 | GO35: 9 | GP35: 10 | GQ35: 11 | GR35: 12 | GS35: 13 | GT35: 27 | GU35: 28 | GV35: 16 | GW35: 17 | GX35: 18 | GY35: 19 | GZ35: 20 | HA35: 27 | HB35: 28 | HC35: 23 | HD35: 24 | HE35: 25 | HF35: 26 | HG35: 27 | HH35: 27 | HI35: 28 | HJ35: 30
A36: Termin 1 30 % | B36: MD ROYALTY Implementation Task | C36: 100 | D36: 100
B37: Termin 1 | C37: 30 | D37: =(D38+D41) -> 30
B38: Project Preparation | C38: 5 | D38: =sum(D39:D40) -> 5
B39: Kick Off | C39: 2 | D39: =sum(E39:HJ39) -> 2 | E39: 1 | J39: 1
B40: Project Charter | C40: 3 | D40: =sum(E40:HJ40) -> 3 | L40: 1 | P40: 0.5 | X40: 1 | AC40: 0.5
B41: Requirement Preparation | C41: 25 | D41: =sum(D42:D43) -> 25
B42: Gap Analysis | C42: 10 | D42: =sum(E42:HJ42) -> 10 | K42: 0.5 | L42: 1 | Q42: 0.5 | R42: 0.5 | S42: 0.5 | V42: 1 | W42: 1 | X42: 1 | Y42: 0.5 | Z42: 1 | AC42: 1 | AD42: 1 | AE42: 0.5
...

Sheet Sheet1
B3: 1

Sheet Timeline
A3: No | B3: Keterangan | C3: Total Plan | D3: Plan Now | E3: Real | F3: Maret | J3: April | N3: May | S3: June | W3: July | AB3: Agust
F4: W1 | G4: W2 | H4: W3 | I4: W4 | J4: W5 | L4: W6 | M4: W7 | N4: W8 | O4: W9 | P4: W10 | Q4: W11 | R4: W12 | S4: W13 | T4: W14 | U4: W15 | V4: W16 | W4: W17 | X4: W18 | Y4: W19 | Z4: W20 | AA4: W21 | AB4: W22 | AC4: W23 | AD4: W24 | AE4: W25
A5: 1 | B5: Project Preparation | C5: =C6 -> 1 | D5: 1 | E5: =E6 -> 1
B6: Kick Off | C6: 1 | D6: 1 | E6: =Task_Table!D34 -> 1
A7: 2 | B7: Requirement Preparation | C7: =C8+C9+C10 -> 29 | D7: 15 | E7: =sum(E8:E10) -> 7.3
B8: Gap Analysis | C8: 6 | D8: =Sum(D9:D10) -> 28 | E8: =Task_Table!D36 -> 3.5
B9: Blue Print | C9: 6 | D9: 2 | E9: =Task_Table!D37 -> 1.9
B10: Mockup | C10: 17 | D10: 26 | E10: =Task_Table!D38 -> 1.9
A11: 3 | B11: Enhanchement | C11: =C12+C13+C14 -> 49 | D11: =Sum(D12:D17) -> 56 | E11: =sum(E12:E14) -> 0
B12: Environment Preparation | C12: 1 | D12: 1 | E12: =Task_Table!D41 -> 0
B13: Development | C13: 45 | D13: 45 | E13: =Task_Table!D42 -> 0
B14: Unit Testing | C14: 3 | D14: 3 | E14: =Task_Table!D43 -> 0
A15: 4 | B15: Acceptance | C15: =C16+C17+C18 -> 16 | D15: 2 | E15: =sum(E16:E18) -> 0
B16: SIT | C16: 3 | D16: 3 | E16: =Task_Table!D45 -> 0
B17: UAT | C17: 10 | D17: 2 | E17: =Task_Table!D46 -> 0
B18: EUT | C18: 3 | D18: =Sum(D19:D20) -> 7 | E18: =Task_Table!D47 -> 0
A19: 5 | B19: Support | C19: =C20 -> 5 | D19: 2 | E19: =E20 -> 0
B20: Support | C20: 5 | D20: 5 | E20: =Task_Table!D50 -> 0
A21: Total | C21: =C5+C7+C11+C15+C19 -> 100 | D21: =#REF!+D8+D11+D18+#REF! -> #REF! | E21: =#REF!+E8+E11+E18+#REF! -> #REF!
O23: Data | P23: =7-5.3 -> 1.7
B24: =B23*3 -> 0 | H24: Cuti Bersama Lebaran | O24: upload | P24: =3-1.4 -> 1.6
H25: Migration
H26: Transport to Production | P26: =P23+P24+P25 -> 3.3
H27: Activity Done | P27: =4.5-P26 -> 1.2
H28: Activity In Progress
H29: Planning
H30: Go Live

Sheet Copy of Timeline
A3: No | B3: Keterangan | C3: Total Plan | D3: Plan Now | E3: Real | F3: Maret | J3: April | N3: May | S3: June | W3: July | AB3: August | AF3: Septem | AJ3: Oktober
F4: W1 | G4: W2 | H4: W3 | I4: W4 | J4: W5 | L4: W6 | M4: W7 | N4: W8 | O4: W9 | P4: W10 | Q4: W11 | R4: W12 | S4: W13 | T4: W14 | U4: W15 | V4: W16 | W4: W17 | X4: W18 | Y4: W19 | Z4: W20 | AA4: W21 | AB4: W22 | AC4: W23 | AD4: W24 | AE4: W25 | AF4: W26 | AG4: W27 | AH4: W28 | AI4: W29 | AJ4: W30 | AK4: W31 | AL4: W32 | AM4: W33
A5: 1 | B5: Requirement & Preparation | C5: 30 | D5: =Sum(D6:D8) -> 30 | E5: =#REF! -> #REF!
B6: Kick Off & Project Charter | C6: 5 | D6: 5 | E6: =#REF! -> #REF!
B7: Gap Analysis | C7: 10 | D7: 10 | E7: =#REF! -> #REF!
B8: Blueprint | C8: 15 | D8: 15 | E8: =#REF! -> #REF!
A9: 2 | B9: Enhancement | C9: 33 | D9: =Sum(D10:D12) -> 33 | E9: =#REF! -> #REF!
B10: Environment Preparation | C10: 2 | D10: 2 | E10: =#REF! -> #REF!
B11: Development | C11: 26 | D11: 26 | E11: =#REF! -> #REF!
B12: Unit Testing | C12: 5 | D12: 5 | E12: =#REF! -> #REF!
A13: 3 | B13: Acceptance | C13: 20 | D13: =Sum(D14:D19) -> 20 | E13: =#REF! -> #REF!
B14: SIT Order Management | C14: 3 | D14: 3 | E14: 3
B15: SIT Penagihan Royalty | C15: 2 | D15: 2 | E15: 2
B16: UAT Order Management | C16: 8 | D16: 8 | E16: 8
B17: UAT Penagihan Royalty | C17: 2 | D17: 2 | E17: 2
B18: EUT Order Management | C18: 3 | D18: 3 | E18: 3
B19: EUT Penagihan Royalty | C19: 2 | D19: 2 | E19: 2
A20: 4 | B20: Live Preparation | C20: =Sum(C21:C23) -> 15 | D20: =Sum(D21:D23) -> 15 | E20: =Sum(E21:E23) -> 15
B21: Data Preparation | C21: 8 | D21: 8 | E21: 8
B22: Upload Migration to Production | C22: 5 | D22: 5 | E22: 5
B23: Transport ke Production | C23: 2 | D23: 2 | E23: 2
A24: 5 | B24: Go Live | C24: 1 | D24: 1 | E24: 1
A25: 6 | B25: Support | C25: 1 | D25: =D26 -> 0 | E25: =#REF! -> #REF!
B26: Support | C26: 1 | D26: 0 | E26: =#REF! -> #REF!
A27: Total | C27: =C5+C9+C13+C20+C24+C25 -> 100 | D27: =D5+D9+D13+D20+D24+D25 -> 99 | E27: =E5+E9+E13+E20+E25+E24 -> #REF!
D29: =D21-E21 -> 0 | O29: Data | P29: =7-5.3 -> 1.7
B30: =B29*3 -> 0 | H30: Cuti Bersama Lebaran | O30: upload | P30: =3-1.4 -> 1.6
H31: Migration
H32: Transport to Production | P32: =P29+P30+P31 -> 3.3
H33: Activity Done | P33: =4.5-P32 -> 1.2
H34: Activity In Progress
H35: Planning
H36: Go Live

Sheet Kurva S
C29: W1 | D29: W2 | E29: W3 | F29: W4 | G29: W5 | H29: W6 | I29: W7 | J29: W8 | K29: W9 | L29: W10 | M29: W11 | N29: W12 | O29: W13 | P29: W14 | Q29: W15 | R29: W16 | S29: W17 | T29: W18 | U29: W19 | V29: W20 | W29: W21 | X29: W22 | Y29: W23 | Z29: W24 | AA29: W25
B30: Planning | C30: 9 | D30: 24 | E30: 39 | F30: =Task_Table!AE53 -> 32 | G30: =Task_Table!AM53 -> 33 | I30: 56 | J30: 62 | K30: 66 | L30: 76 | M30: 76 | N30: 76 | O30: 76 | P30: 84 | Q30: 89 | R30: 90 | S30: =#REF! -> #REF! | T30: =#REF! -> #REF! | U30: 93 | V30: 94 | W30: 96 | X30: 97 | Y30: 98 | Z30: 98 | AA30: 99
B31: Realisasi | C31: 6.5 | D31: 14 | E31: 31 | F31: =#REF! -> #REF! | G31: 38 | I31: 50.7 | J31: 56.5 | K31: 60.5 | L31: 68.3 | M31: 72.7 | N31: 72.7 | O31: 73.2 | P31: 79.7 | Q31: 82 | R31: 83 | S31: =#REF! -> #REF! | T31: =#REF! -> #REF! | U31: 89.7 | V31: 90.9 | W31: 93.2 | X31: 95.5 | Y31: 96.5 | Z31: 97 | AA31: 99
B32: Gap | C32: =C30-C31 -> 2.5 | D32: =D30-D31 -> 10 | E32: =E30-E31 -> 8 | F32: =F30-F31 -> #REF! | G32: =G30-G31 -> -5 | I32: =I30-I31 -> 5.3 | J32: =J30-J31 -> 5.5 | K32: =K30-K31 -> 5.5 | L32: =L30-L31 -> 7.7 | M32: =M30-M31 -> 3.3 | N32: =M30-M31 -> 3.3 | O32: =O30-O31 -> 2.8 | P32: =P30-P31 -> 4.3 | Q32: =Q30-Q31 -> 7 | R32: =R30-R31 -> 7 | S32: =S30-S31 -> #REF! | T32: =T30-T31 -> #REF! | U32: =U30-U31 -> 3.3 | V32: =V30-V31 -> 3.1 | ... AA32: =AA30-AA31 -> 0

Sheet Copy of Kurva S
C29: W1 | D29: W2 | E29: W3 | F29: W4 | G29: W5 | H29: W6 | I29: W7 | J29: W8 | K29: W9 | L29: W10 | M29: W11 | N29: W12 | O29: W13 | P29: W14 | Q29: W15 | R29: W16 | S29: W17 | T29: W18 | U29: W19 | V29: W20 | W29: W21
B30: Planning | C30: 9 | D30: 24 | E30: 39 | F30: =Task_Table!AE53 -> 32 | G30: =Task_Table!AM53 -> 33 | I30: 56 | J30: 62 | K30: 66 | L30: 76 | M30: 76 | N30: 76 | O30: 76 | P30: 84 | Q30: 89 | R30: 90 | S30: =#REF! -> #REF! | T30: =#REF! -> #REF! | U30: 93 | V30: 94 | W30: 95
B31: Realisasi | C31: 6.5 | D31: 14 | E31: 31 | F31: =#REF! -> #REF! | G31: 38 | I31: 50.7 | J31: 56.5 | K31: 60.5 | L31: 68.3 | M31: 72.7 | N31: 72.7 | O31: 73.2 | P31: 79.7 | Q31: 82 | R31: 83 | S31: =#REF! -> #REF! | T31: =#REF! -> #REF! | U31: 89.7 | V31: 90.9 | W31: 92.3
B32: Gap | C32: =C30-C31 -> 2.5 | D32: =D30-D31 -> 10 | E32: =E30-E31 -> 8 | F32: =F30-F31 -> #REF! | G32: =G30-G31 -> -5 | I32: =I30-I31 -> 5.3 | J32: =J30-J31 -> 5.5 | K32: =K30-K31 -> 5.5 | L32: =L30-L31 -> 7.7 | M32: =M30-M31 -> 3.3 | N32: =M30-M31 -> 3.3 | O32: =O30-O31 -> 2.8 | P32: =P30-P31 -> 4.3 | Q32: =Q30-Q31 -> 7 | R32: =R30-R31 -> 7 | S32: =S30-S31 -> #REF! | T32: =T30-T31 -> #REF! | U32: =U30-U31 -> 3.3 | V32: =V30-V31 -> 3.1 | W32: =W30-W31 -> 2.7
I40: muter2 da wkkw

Sheet Master Data
B2: Master Data | D2: 1 | E2: 2 | F2: 3 | G2: 4 | H2: 5 | I2: 6 | J2: 7 | K2: 8 | L2: 9 | M2: 10 | N2: 11 | O2: 12 | P2: 13 | Q2: 14 | R2: 15 | S2: 16 | T2: 17 | U2: 18 | V2: 19 | W2: 20 | X2: 21 | Y2: 22 | Z2: 23
B3: Master Material & Kode Material
B4: Material vs Plant
B5: Semen Zak vs Kantong
B6: Material MD
B7: Brand vs Semen Zak
B8: Brand vs Plant vs Royalty
B9: Demand Marketing
B10: Target Distribution
B11: Mapping Ship To
B12: Sourcing Plant
B13: Pricing Semen
B14: Semen Zak vs Kantong vs Distrik
... B21: Jatah Expediture
