Workbook

Sheet Sheet1
A1: Vessel Code | B1: Vessel Name | C1: KAPAL AKTIF 6 BLN | D1: MMSI | E1: Type | F1: Status | G1: Agent | H1: Principal | I1: Flag | J1: DWT | K1: Length | L1: Gross Ton | M1: Horsepower | N1: Draft | O1: LOP | P1: Call Sign | Q1: Direct Call | R1: Country Made | S1: Liner/Tramper | T1: Profile | U1: Hatch Type | V1: Total Hatch | W1: Branch | X1: Status Active | Y1: Update By | Z1: Update Ts | AA1: Document
A2: 1324 | B2: MV. PORT PEGASUS | C2: =VLOOKUP(B2,Sheet2!$A$2:$A$392,1,0) -> #N/A | E2: CARGO | F2: I | G2: TONASA LINES PT | I2: Hongkong | J2: 39675 | K2: 177 | L2: 19887 | M2: 6620 | N2: 10.01 | P2: VRAA8 | R2: Japan | S2: TRAMPER | T2: Y | U2: MAC GREGOR | V2: 4 | X2: Y | Y2: scm_darat1@demo.com | Z2: 14/01/2022 12:42 | AA2: Open
A3: 1603 | B3: TB. BLORO 1603 / BG. ROBBY 320 | C3: =VLOOKUP(B3,Sheet2!$A$2:$A$392,1,0) -> TB. BLORO 1603 / BG. ROBBY 320 | E3: TUG BOAT / TONGKANG | F3: D | G3: TONASA LINES PT | I3: Indonesia | J3: 8000 | K3: 91 | L3: 3317 | P3: YDC6525 | R3: Indonesia | S3: TRAMPER | T3: Y | U3: PONTHON | X3: Y | Y3: mursida.h@sig.id | Z3: 09/03/2025 21:09 | AA3: Open
A4: 1709 | B4: TB. KALTIM DOLPHIN 17-09 / BG. KALTIM FT 80-11 | C4: =VLOOKUP(B4,Sheet2!$A$2:$A$392,1,0) -> TB. KALTIM DOLPHIN 17-09 / BG. KALTIM FT 80-11 | E4: TUG BOAT / TONGKANG | F4: D | G4: TONASA LINES PT | I4: Indonesia | J4: 8000 | K4: 91 | L4: 3315 | P4: YDA6386 | R4: Indonesia | S4: TRAMPER | T4: Y | U4: PONTHON | X4: Y | Y4: mursida.h@sig.id | Z4: 05/12/2024 19:39 | AA4: Open
A5: 4RDI | B5: MV MOHAR | C5: =VLOOKUP(B5,Sheet2!$A$2:$A$392,1,0) -> #N/A | E5: BULK CARRIER | F5: I | G5: KARYA MUDA AGENCY PT | I5: Srilangka | J5: 22530 | K5: 154.35 | L5: 14260 | M5: 6345 | P5: 4RDI | R5: Srilangka | S5: TRAMPER | T5: Y | U5: MAC GREGOR | X5: Y | Y5: farizd@primus.co.id | Z5: 25/04/2022 10:50 | AA5: Open
A6: 4SSM | B6: MV. MEGHNA HARMONY | C6: =VLOOKUP(B6,Sheet2!$A$2:$A$392,1,0) -> #N/A | E6: BULK CARRIER | F6: I | G6: VARIA USAHA LINTAS SEGARA, PT | I6: Bangladesh | J6: 56019 | K6: 189.99 | L6: 31247 | O6: VUS | P6: S2BD4 | R6: Bangladesh | S6: TRAMPER | T6: Y | U6: MAC GREGOR | W6: TUBAN | X6: Y | Y6: bupvuba@gmail.com | Z6: 14/11/2024 09:58 | AA6: Open
A7: 4SST | B7: TB. ASIA TIRTA 1601 / BG. ASIA PERDANA 2706 | C7: =VLOOKUP(B7,Sheet2!$A$2:$A$392,1,0) -> TB. ASIA TIRTA 1601 / BG. ASIA PERDANA 2706 | E7: TUG BOAT / TONGKANG | F7: D | G7: VARIA USAHA LINTAS SEGARA, PT | I7: Indonesia | J7: 4480 | K7: 80.77 | L7: 1465 | O7: VUS | P7: YDA 3115 | R7: Indonesia | S7: TRAMPER | T7: Y | U7: PONTHON | W7: TUBAN | X7: Y | Y7: bupvuba@gmail.com | Z7: 07/01/2025 18:14 | AA7: Open
A8: A-05 | B8: ASIABAY - 105 | C8: =VLOOKUP(B8,Sheet2!$A$2:$A$392,1,0) -> #N/A | E8: TONGKANG | G8: PELAYARAN SEMOGA SUKSES, PT | I8: Indonesia | J8: 3137 | K8: 91.52 | L8: 3137 | P8: - | S8: TRAMPER | X8: Y | AA8: Open
A9: A003 | B9: ADAS 03 | C9: =VLOOKUP(B9,Sheet2!$A$2:$A$392,1,0) -> #N/A | E9: TUG BOAT / TONGKANG | G9: ADAS SEJAHTERA SAMUDRA LINES, PT | I9: Indonesia | J9: 121 | K9: 22.87 | L9: 121 | P9: YD6566 | S9: TRAMPER | X9: Y | AA9: Open
A10: A007 | B10: TB. ASINDO 007 / BG. ASINDO 010 | C10: =VLOOKUP(B10,Sheet2!$A$2:$A$392,1,0) -> TB. ASINDO 007 / BG. ASINDO 010 | E10: TUG BOAT / TONGKANG | F10: D | G10: TONASA LINES PT | I10: Indonesia | J10: 5000 | K10: 82 | L10: 2305 | P10: YDA3618 | R10: Indonesia | S10: TRAMPER | T10: Y | U10: PONTHON | X10: Y | Y10: mursida.h@sig.id | Z10: 27/01/2025 18:08 | AA10: Open
A11: A103 | B11: TB. MAHESA 104 / BG. ALIKA 103 | C11: =VLOOKUP(B11,Sheet2!$A$2:$A$392,1,0) -> #N/A | E11: TUG BOAT / TONGKANG | F11: D | G11: TONASA LINES PT | I11: Indonesia | J11: 8000 | K11: 91 | L11: 3469 | P11: YDA6596 | R11: Indonesia | S11: TRAMPER | T11: Y | U11: PONTHON | X11: Y | Y11: mursida.h@sig.id | Z11: 11/10/2024 18:38 | AA11: Open
A12: A111 | B12: ANUGRAH 11 | C12: =VLOOKUP(B12,Sheet2!$A$2:$A$392,1,0) -> #N/A | E12: TUG BOAT / TONGKANG | G12: DUTA BAHTERA LINE, PT | I12: Indonesia | J12: 42 | K12: 22.12 | L12: 138 | P12: YDB 4455 | S12: TRAMPER | X12: Y | AA12: Open
A13: A138 | B13: AYU 138 | C13: =VLOOKUP(B13,Sheet2!$A$2:$A$392,1,0) -> #N/A | E13: LCT | G13: BUNGA NUSA MAHAKAM, PT | I13: Indonesia | J13: 2255 | K13: 80.78 | L13: 1503 | P13: PNRU | S13: TRAMPER | X13: Y | Y13: WSDL | Z13: 06/12/2017 14:47 | AA13: Open
A14: A230 | B14: ASIAPRIDE 23130 | C14: =VLOOKUP(B14,Sheet2!$A$2:$A$392,1,0) -> #N/A | E14: TONGKANG | G14: ASIA TIRTA PERDANA, PT | I14: Indonesia | J14: 402 | K14: 70.14 | L14: 1339 | P14: - | S14: TRAMPER | X14: Y | Y14: WSDL | Z14: 16/11/2017 16:54 | AA14: Open
A15: A404 | B15: ABADI 4 | C15: =VLOOKUP(B15,Sheet2!$A$2:$A$392,1,0) -> #N/A | E15: TUG BOAT / TONGKANG | F15: D | G15: BAHARI TIRTA JAYA, PT | I15: Indonesia | J15: 190 | K15: 25.3 | L15: 190 | P15: YDA 6178 | S15: TRAMPER | T15: N | X15: Y | Y15: 4ndi.4rnold@gmail.com | Z15: 11/12/2017 11:36 | AA15: Open
A16: A618 | B16: AYU 618 | C16: =VLOOKUP(B16,Sheet2!$A$2:$A$392,1,0) -> #N/A | E16: LCT | G16: BUNGA NUSA MAHAKAM, PT | I16: Indonesia | J16: 600 | K16: 52.2 | L16: 343 | P16: YHWO | S16: TRAMPER | X16: Y | AA16: Open
A17: A808 | B17: ARIN 8 | C17: =VLOOKUP(B17,Sheet2!$A$2:$A$392,1,0) -> #N/A | E17: CURAH CAIR | F17: D | G17: PERTAMINA TRANS KONTINENTAL, PT | I17: Indonesia | J17: 8834 | K17: 112.5 | L17: 5483 | P17: JZAR | S17: TRAMPER | T17: Y | U17: MAC GREGOR | X17: Y | Y17: mambrasar.saint@gmail.com | Z17: 24/11/2017 21:32 | AA17: Open
A18: A881 | B18: ANINDHITA 81 | C18: =VLOOKUP(B18,Sheet2!$A$2:$A$392,1,0) -> #N/A | E18: SPOB/BUNKER | I18: Indonesia | J18: 4532 | K18: 87.11 | L18: 2999 | P18: JZVX | S18: TRAMPER | X18: Y | AA18: Open
A19: A888 | B19: ATMANIWEDHANA 88 | C19: =VLOOKUP(B19,Sheet2!$A$2:$A$392,1,0) -> #N/A | E19: CARGO | G19: SINAR PASIFIC, PT | I19: Indonesia | J19: 2999 | K19: 87.11 | L19: 2999 | P19: JZPX | S19: TRAMPER | X19: Y | AA19: Open
A20: A889 | B20: ARWANA 88 | C20: =VLOOKUP(B20,Sheet2!$A$2:$A$392,1,0) -> #N/A | E20: TUG BOAT / TONGKANG | F20: D | G20: PELAYARAN SKREN SARANA SMD, PT | I20: Indonesia | J20: 123 | K20: 23 | L20: 123 | O20: SES | P20: YDA 6755 | R20: Indonesia | S20: TRAMPER | T20: Y | U20: MAC GREGOR | X20: Y | Y20: arifpelindo4bpp@gmail.com | Z20: 07/12/2017 14:47 | AA20: Open
A21: AA03 | B21: ADMIRAL AMIR 2 | C21: =VLOOKUP(B21,Sheet2!$A$2:$A$392,1,0) -> #N/A | E21: LCT | G21: PELAYARAN LESTARI ABADI SAKTI, PT | I21: Indonesia | J21: 207 | K21: 59.61 | L21: 689 | P21: J Z X G | S21: TRAMPER | X21: Y | AA21: Open
A22: AB09 | B22: ASIA BAY 109 | C22: =VLOOKUP(B22,Sheet2!$A$2:$A$392,1,0) -> #N/A | E22: TONGKANG | G22: PELAYARAN SEMOGA SUKSES, PT | I22: Indonesia | J22: 3165 | K22: 91.5 | L22: 3165 | P22: - | S22: TRAMPER | X22: Y | AA22: Open
A23: ABBA | B23: ABBA MV | C23: =VLOOKUP(B23,Sheet2!$A$2:$A$392,1,0) -> #N/A | E23: CARGO | F23: D | G23: TONASA LINES PT | I23: Indonesia | J23: 50 | K23: 170 | L23: 570 | P23: ABBA | R23: Indonesia | S23: TRAMPER | T23: N | U23: PONTHON | X23: Y | Y23: henky@primus.co.id | Z23: 18/12/2021 22:12 | AA23: Open
A24: ABII | B24: KM ANUGERAH BUANA III | C24: =VLOOKUP(B24,Sheet2!$A$2:$A$392,1,0) -> #N/A | E24: CARGO | F24: D | G24: VARIA USAHA LINTAS SEGARA, PT | I24: Bangladesh | J24: 2167 | K24: 70 | L24: 1445 | O24: VUS | P24: YHXK | R24: Indonesia | S24: TRAMPER | T24: Y | U24: PONTHON | W24: TUBAN | X24: R | Y24: bupvuba@gmail.com | Z24: 23/04/2025 09:04 | AA24: Open
A25: ABLH | B25: MV. ABDULLAH | C25: =VLOOKUP(B25,Sheet2!$A$2:$A$392,1,0) -> #N/A | E25: BULK CARRIER | F25: I | G25: WAHYU SAMUDRO MULYO PADANG PT | J25: 46862 | K25: 185.74 | L25: 26070 | M25: 10150 | N25: 12 | O25: WSM | P25: S2CW | R25: Japan | S25: TRAMPER | U25: MAC GREGOR | V25: 5 | X25: Y | Y25: panji.agrama@sig.id | Z25: 08/04/2023 11:50 | AA25: Open
A26: ABVI | B26: KM ANUGRAH BUANA VI | C26: =VLOOKUP(B26,Sheet2!$A$2:$A$392,1,0) -> #N/A | E26: CARGO | F26: D | G26: ELANO KUSUMA SHIPPING, PT | J26: 3861 | K26: 88.8 | L26: 2302 | O26: EKS | P26: PMIE | R26: Indonesia | S26: TRAMPER | U26: MAC GREGOR | W26: TUBAN | X26: Y | Y26: bupvuba@gmail.com | Z26: 22/12/2022 09:21 | AA26: Open
A27: ADRW | B27: KM. ANDREW | C27: =VLOOKUP(B27,Sheet2!$A$2:$A$392,1,0) -> #N/A | E27: CARGO | F27: D | G27: TONASA LINES PT | I27: Indonesia | J27: 2000 | K27: 59 | L27: 1168 | M27: 1000 | N27: 4.27 | P27: PNPS | R27: Japan | S27: TRAMPER | T27: Y | U27: MAC GREGOR | W27: BIRINGKASSI | X27: Y | Y27: wellem.ariance@sig.id | Z27: 13/07/2022 20:00 | AA27: Open
A28: AENT | B28: ANGGRAINI EXCELLENT | C28: =VLOOKUP(B28,Sheet2!$A$2:$A$392,1,0) -> #N/A | E28: TANKER | I28: Indonesia | J28: 3500 | K28: 90 | L28: 2600 | P28: PNDK | S28: TRAMPER | X28: Y | AA28: Open
A29: AFSA | B29: SOECHI PRESTASI III | C29: =VLOOKUP(B29,Sheet2!$A$2:$A$392,1,0) -> #N/A | E29: TANKER | I29: Indonesia | J29: 17428 | K29: 70.95 | L29: 986 | P29: YHCO | S29: TRAMPER | X29: Y | AA29: Open
A30: AGAG | B30: KM. ANUGRAH AGUNG | C30: =VLOOKUP(B30,Sheet2!$A$2:$A$392,1,0) -> #N/A | E30: CARGO | F30: D | G30: TONASA LINES PT | I30: Indonesia | J30: 2250 | K30: 70 | L30: 1150 | P30: POYZ | R30: Indonesia | S30: TRAMPER | T30: Y | U30: MAC GREGOR | X30: Y | Y30: mursida.h@sig.id | Z30: 29/08/2023 07:19 | AA30: Open
A31: AGAL | B31: ASIKE GLOBAL | C31: =VLOOKUP(B31,Sheet2!$A$2:$A$392,1,0) -> #N/A | E31: CARGO | G31: KARANA LINE, PT | I31: Indonesia | J31: 6174 | K31: 98.66 | L31: 5284 | P31: POOT | S31: TRAMPER | X31: Y | AA31: Open
A32: AGR8 | B32: KM. ANUGERAH VIII | C32: =VLOOKUP(B32,Sheet2!$A$2:$A$392,1,0) -> KM. ANUGERAH VIII | E32: CARGO | F32: D | G32: ELANO KUSUMA SHIPPING, PT | J32: 2000 | K32: 56 | L32: 1257 | O32: EKS | P32: 0000 | R32: Japan | S32: TRAMPER | U32: MAC GREGOR | W32: TUBAN | X32: Y | Y32: bupvuba@gmail.com | Z32: 13/03/2025 07:54 | AA32: Open
A33: AI09 | B33: TB. ARMADA INTAN 09 / BG. SMR 2509 | C33: =VLOOKUP(B33,Sheet2!$A$2:$A$392,1,0) -> #N/A | E33: TUG BOAT / TONGKANG | F33: D | G33: VARIA USAHA LINTAS SEGARA, PT | I33: Indonesia | J33: 3020 | K33: 78 | L33: 2013 | M33: 2000 | N33: 6 | P33: YDA 0918 | R33: Indonesia | S33: TRAMPER | T33: Y | U33: PONTHON | W33: TUBAN | X33: Y | Y33: bupvuba@gmail.com | Z33: 19/03/2022 15:46 | AA33: Open
A34: AILM | B34: KLM. ANUGRAH INDAH | C34: =VLOOKUP(B34,Sheet2!$A$2:$A$392,1,0) -> #N/A | E34: CARGO | F34: D | G34: TONASA LINES PT | J34: 210 | K34: 70 | L34: 150 | P34: AILM | Q34: Y | R34: Indonesia | S34: TRAMPER | U34: MAC GREGOR | X34: Y | Y34: mursida.h@sig.id | Z34: 08/04/2024 17:58 | AA34: Open
A35: AITA | B35: MV ADVAITA | C35: =VLOOKUP(B35,Sheet2!$A$2:$A$392,1,0) -> #N/A | E35: CEMENT CARRIER | F35: I | G35: WAHYU SAMUDRO MULYO PADANG PT | I35: India | J35: 22701 | K35: 159.5 | L35: 14666 | M35: 4500 | N35: 9.2 | O35: WSM | P35: VTHA | R35: India | S35: TRAMPER | T35: Y | U35: MAC GREGOR | X35: Y | Y35: farizd@primus.co.id | Z35: 26/03/2022 21:48 | AA35: Open
A36: AJ07 | B36: AS JAYA - 7 | C36: =VLOOKUP(B36,Sheet2!$A$2:$A$392,1,0) -> #N/A | E36: TUG BOAT / TONGKANG | G36: ANDALAN LANCAR BAHARI, PT | I36: Indonesia | J36: 1 | K36: 30.2 | L36: 292 | P36: YDB4832 | S36: TRAMPER | X36: Y | AA36: Open
A37: AJLM | B37: KLM. ASRI INDAH II | C37: =VLOOKUP(B37,Sheet2!$A$2:$A$392,1,0) -> #N/A | E37: PLM/KLM | F37: D | G37: TONASA LINES PT | J37: 400 | K37: 70 | L37: 150 | P37: 1 | Q37: Y | R37: Indonesia | S37: TRAMPER | U37: MAC GREGOR | X37: Y | Y37: mursida.h@sig.id | Z37: 08/04/2024 17:59 | AA37: Open
A38: AJY1 | B38: ARKA JAYA | C38: =VLOOKUP(B38,Sheet2!$A$2:$A$392,1,0) -> #N/A | E38: CARGO | G38: ARGHANIAGA PANCATUNGGAL, PT | I38: Indonesia | J38: 186 | K38: 24.8 | L38: 66 | P38: YB 6411 | S38: TRAMPER | X38: Y | AA38: Open
A39: AKHG | B39: MV AKIJ HERITAGE | C39: =VLOOKUP(B39,Sheet2!$A$2:$A$392,1,0) -> #N/A | E39: BULK CARRIER | F39: I | G39: VARIA USAHA LINTAS SEGARA, PT | I39: Bangladesh | J39: 56055 | K39: 189.99 | L39: 31236 | O39: VUS | P39: S2ACS | R39: Bangladesh | S39: TRAMPER | T39: Y | U39: MAC GREGOR | W39: TUBAN | X39: Y | Y39: bupvuba@gmail.com | Z39: 18/02/2025 08:25 | AA39: Open
A40: AKIO | B40: MV. AKIJ OCEAN | C40: =VLOOKUP(B40,Sheet2!$A$2:$A$392,1,0) -> MV. AKIJ OCEAN | E40: BULK CARRIER | F40: I | G40: VARIA USAHA LINTAS SEGARA, PT | J40: 45736 | K40: 185.74 | L40: 25982 | O40: VUS | P40: S2AE6 | R40: Bangladesh | S40: TRAMPER | U40: MAC GREGOR | W40: TUBAN | X40: Y | Y40: bupvuba@gmail.com | Z40: 01/01/2025 16:36 | AA40: Open
...

Sheet Sheet2
A1: KAPAL | B1: INT DOM | C1: EXP DOM
A2: PERMATA PRIMA | B2: int_dom: "DOM" | C2: exp_dom: "DOM"
A3: SABUK NUSANTARA 37 | B3: int_dom: "DOM" | C3: exp_dom: "DOM"
A4: SEJAHTERA 32 | B4: int_dom: "INT" | C4: exp_dom: "DOM"
A5: SHINPO | B5: int_dom: "DOM" | C5: exp_dom: "DOM"
A6: TONASA LINE XV | B6: int_dom: "INT" | C6: exp_dom: "DOM"
A7: UNEI | B7: int_dom: "DOM" | C7: exp_dom: "DOM"
A8: BERKAT MAKMUR 8 | B8: int_dom: "INT" | C8: exp_dom: "DOM"
A9: BG. OCEANUS 32TB. MHKL 207 | B9: int_dom: "DOM" | C9: exp_dom: "DOM"
A10: CITRA NUSANTARA 01 | B10: int_dom: "DOM" | C10: exp_dom: "DOM"
A11: FORTUNE ISLAND | B11: int_dom: "INT" | C11: exp_dom: "EXP"
A12: GRACIA 18 | B12: int_dom: "INT" | C12: exp_dom: "DOM"
... A392: UNEI | B392: int_dom: "DOM" | C392: exp_dom: "DOM"
